2023-12-11 11:45:44,141 ERROR scheduler Exception in Enqueue Events for Site klms.com
Traceback (most recent call last):
  File "/home/sujay/lms/frappe-bench/apps/frappe/frappe/utils/scheduler.py", line 73, in enqueue_events_for_site
    if is_scheduler_inactive():
  File "/home/sujay/lms/frappe-bench/apps/frappe/frappe/utils/scheduler.py", line 110, in is_scheduler_inactive
    if is_scheduler_disabled(verbose=verbose):
  File "/home/sujay/lms/frappe-bench/apps/frappe/frappe/utils/scheduler.py", line 123, in is_scheduler_disabled
    frappe.db.get_single_value("System Settings", "enable_scheduler")
  File "/home/sujay/lms/frappe-bench/apps/frappe/frappe/database/database.py", line 776, in get_single_value
    ).run()
  File "/home/sujay/lms/frappe-bench/apps/frappe/frappe/query_builder/utils.py", line 87, in execute_query
    result = frappe.db.sql(query, params, *args, **kwargs)  # nosemgrep
  File "/home/sujay/lms/frappe-bench/apps/frappe/frappe/database/database.py", line 194, in sql
    self.connect()
  File "/home/sujay/lms/frappe-bench/apps/frappe/frappe/database/database.py", line 109, in connect
    self._conn = self.get_connection()
  File "/home/sujay/lms/frappe-bench/apps/frappe/frappe/database/mariadb/database.py", line 102, in get_connection
    conn = self._get_connection()
  File "/home/sujay/lms/frappe-bench/apps/frappe/frappe/database/mariadb/database.py", line 108, in _get_connection
    return self.create_connection()
  File "/home/sujay/lms/frappe-bench/apps/frappe/frappe/database/mariadb/database.py", line 111, in create_connection
    return pymysql.connect(**self.get_connection_settings())
  File "/home/sujay/lms/frappe-bench/env/lib/python3.10/site-packages/pymysql/connections.py", line 358, in __init__
    self.connect()
  File "/home/sujay/lms/frappe-bench/env/lib/python3.10/site-packages/pymysql/connections.py", line 664, in connect
    self._request_authentication()
  File "/home/sujay/lms/frappe-bench/env/lib/python3.10/site-packages/pymysql/connections.py", line 954, in _request_authentication
    auth_packet = self._read_packet()
  File "/home/sujay/lms/frappe-bench/env/lib/python3.10/site-packages/pymysql/connections.py", line 772, in _read_packet
    packet.raise_for_error()
  File "/home/sujay/lms/frappe-bench/env/lib/python3.10/site-packages/pymysql/protocol.py", line 221, in raise_for_error
    err.raise_mysql_exception(self._data)
  File "/home/sujay/lms/frappe-bench/env/lib/python3.10/site-packages/pymysql/err.py", line 143, in raise_mysql_exception
    raise errorclass(errno, errval)
pymysql.err.OperationalError: (1045, "Access denied for user '_385d09b426bab63e'@'localhost' (using password: YES)")
2023-12-11 11:46:44,266 ERROR scheduler Exception in Enqueue Events for Site klms.com
Traceback (most recent call last):
  File "/home/sujay/lms/frappe-bench/apps/frappe/frappe/utils/scheduler.py", line 73, in enqueue_events_for_site
    if is_scheduler_inactive():
  File "/home/sujay/lms/frappe-bench/apps/frappe/frappe/utils/scheduler.py", line 110, in is_scheduler_inactive
    if is_scheduler_disabled(verbose=verbose):
  File "/home/sujay/lms/frappe-bench/apps/frappe/frappe/utils/scheduler.py", line 123, in is_scheduler_disabled
    frappe.db.get_single_value("System Settings", "enable_scheduler")
  File "/home/sujay/lms/frappe-bench/apps/frappe/frappe/database/database.py", line 776, in get_single_value
    ).run()
  File "/home/sujay/lms/frappe-bench/apps/frappe/frappe/query_builder/utils.py", line 87, in execute_query
    result = frappe.db.sql(query, params, *args, **kwargs)  # nosemgrep
  File "/home/sujay/lms/frappe-bench/apps/frappe/frappe/database/database.py", line 217, in sql
    self._cursor.execute(query, values)
  File "/home/sujay/lms/frappe-bench/env/lib/python3.10/site-packages/pymysql/cursors.py", line 153, in execute
    result = self._query(query)
  File "/home/sujay/lms/frappe-bench/env/lib/python3.10/site-packages/pymysql/cursors.py", line 322, in _query
    conn.query(q)
  File "/home/sujay/lms/frappe-bench/env/lib/python3.10/site-packages/pymysql/connections.py", line 558, in query
    self._affected_rows = self._read_query_result(unbuffered=unbuffered)
  File "/home/sujay/lms/frappe-bench/env/lib/python3.10/site-packages/pymysql/connections.py", line 822, in _read_query_result
    result.read()
  File "/home/sujay/lms/frappe-bench/env/lib/python3.10/site-packages/pymysql/connections.py", line 1200, in read
    first_packet = self.connection._read_packet()
  File "/home/sujay/lms/frappe-bench/env/lib/python3.10/site-packages/pymysql/connections.py", line 772, in _read_packet
    packet.raise_for_error()
  File "/home/sujay/lms/frappe-bench/env/lib/python3.10/site-packages/pymysql/protocol.py", line 221, in raise_for_error
    err.raise_mysql_exception(self._data)
  File "/home/sujay/lms/frappe-bench/env/lib/python3.10/site-packages/pymysql/err.py", line 143, in raise_mysql_exception
    raise errorclass(errno, errval)
pymysql.err.ProgrammingError: (1146, "Table '_385d09b426bab63e.tabSingles' doesn't exist")
2023-12-22 12:49:16,640 ERROR scheduler Exception in Enqueue Events for Site klms.com
Traceback (most recent call last):
  File "/home/sujay/lms/frappe-bench/apps/frappe/frappe/utils/scheduler.py", line 73, in enqueue_events_for_site
    if is_scheduler_inactive():
  File "/home/sujay/lms/frappe-bench/apps/frappe/frappe/utils/scheduler.py", line 110, in is_scheduler_inactive
    if is_scheduler_disabled(verbose=verbose):
  File "/home/sujay/lms/frappe-bench/apps/frappe/frappe/utils/scheduler.py", line 123, in is_scheduler_disabled
    frappe.db.get_single_value("System Settings", "enable_scheduler")
  File "/home/sujay/lms/frappe-bench/apps/frappe/frappe/database/database.py", line 776, in get_single_value
    ).run()
  File "/home/sujay/lms/frappe-bench/apps/frappe/frappe/query_builder/utils.py", line 87, in execute_query
    result = frappe.db.sql(query, params, *args, **kwargs)  # nosemgrep
  File "/home/sujay/lms/frappe-bench/apps/frappe/frappe/database/database.py", line 217, in sql
    self._cursor.execute(query, values)
  File "/home/sujay/lms/frappe-bench/env/lib/python3.10/site-packages/pymysql/cursors.py", line 153, in execute
    result = self._query(query)
  File "/home/sujay/lms/frappe-bench/env/lib/python3.10/site-packages/pymysql/cursors.py", line 322, in _query
    conn.query(q)
  File "/home/sujay/lms/frappe-bench/env/lib/python3.10/site-packages/pymysql/connections.py", line 558, in query
    self._affected_rows = self._read_query_result(unbuffered=unbuffered)
  File "/home/sujay/lms/frappe-bench/env/lib/python3.10/site-packages/pymysql/connections.py", line 822, in _read_query_result
    result.read()
  File "/home/sujay/lms/frappe-bench/env/lib/python3.10/site-packages/pymysql/connections.py", line 1200, in read
    first_packet = self.connection._read_packet()
  File "/home/sujay/lms/frappe-bench/env/lib/python3.10/site-packages/pymysql/connections.py", line 772, in _read_packet
    packet.raise_for_error()
  File "/home/sujay/lms/frappe-bench/env/lib/python3.10/site-packages/pymysql/protocol.py", line 221, in raise_for_error
    err.raise_mysql_exception(self._data)
  File "/home/sujay/lms/frappe-bench/env/lib/python3.10/site-packages/pymysql/err.py", line 143, in raise_mysql_exception
    raise errorclass(errno, errval)
pymysql.err.ProgrammingError: (1146, "Table '_385d09b426bab63e.tabSingles' doesn't exist")
2023-12-22 12:50:16,768 ERROR scheduler Exception in Enqueue Events for Site klms.com
Traceback (most recent call last):
  File "/home/sujay/lms/frappe-bench/apps/frappe/frappe/utils/scheduler.py", line 73, in enqueue_events_for_site
    if is_scheduler_inactive():
  File "/home/sujay/lms/frappe-bench/apps/frappe/frappe/utils/scheduler.py", line 110, in is_scheduler_inactive
    if is_scheduler_disabled(verbose=verbose):
  File "/home/sujay/lms/frappe-bench/apps/frappe/frappe/utils/scheduler.py", line 123, in is_scheduler_disabled
    frappe.db.get_single_value("System Settings", "enable_scheduler")
  File "/home/sujay/lms/frappe-bench/apps/frappe/frappe/database/database.py", line 776, in get_single_value
    ).run()
  File "/home/sujay/lms/frappe-bench/apps/frappe/frappe/query_builder/utils.py", line 87, in execute_query
    result = frappe.db.sql(query, params, *args, **kwargs)  # nosemgrep
  File "/home/sujay/lms/frappe-bench/apps/frappe/frappe/database/database.py", line 217, in sql
    self._cursor.execute(query, values)
  File "/home/sujay/lms/frappe-bench/env/lib/python3.10/site-packages/pymysql/cursors.py", line 153, in execute
    result = self._query(query)
  File "/home/sujay/lms/frappe-bench/env/lib/python3.10/site-packages/pymysql/cursors.py", line 322, in _query
    conn.query(q)
  File "/home/sujay/lms/frappe-bench/env/lib/python3.10/site-packages/pymysql/connections.py", line 558, in query
    self._affected_rows = self._read_query_result(unbuffered=unbuffered)
  File "/home/sujay/lms/frappe-bench/env/lib/python3.10/site-packages/pymysql/connections.py", line 822, in _read_query_result
    result.read()
  File "/home/sujay/lms/frappe-bench/env/lib/python3.10/site-packages/pymysql/connections.py", line 1200, in read
    first_packet = self.connection._read_packet()
  File "/home/sujay/lms/frappe-bench/env/lib/python3.10/site-packages/pymysql/connections.py", line 772, in _read_packet
    packet.raise_for_error()
  File "/home/sujay/lms/frappe-bench/env/lib/python3.10/site-packages/pymysql/protocol.py", line 221, in raise_for_error
    err.raise_mysql_exception(self._data)
  File "/home/sujay/lms/frappe-bench/env/lib/python3.10/site-packages/pymysql/err.py", line 143, in raise_mysql_exception
    raise errorclass(errno, errval)
pymysql.err.ProgrammingError: (1146, "Table '_385d09b426bab63e.tabSingles' doesn't exist")
